Workbook

Sheet Leia-me
A1: Curtailment fotovoltaico — amostra
A3: O que é este arquivo | B3: Amostra gerada a partir dos dados reais do ONS (RESTRICAO_COFF_FOTOVOLTAICA_2026_08 e _2026_09) e do PLD médio semanal publicado pela CCEE. Serve para você conferir o formato antes de escolher os conjuntos definitivos.
A4: Período | B4: 01/08/2026 a 07/09/2026
A5: Conjuntos | B5: 84 conjuntos fotovoltaicos — todos os que o ONS publicou no período. Na versão final entram apenas os seus.
A6: Gerado em | B6: 09/09/2026 11:01 UTC
A8: Fontes
A9: ONS — constrained-off FV | B9: https://dados.ons.org.br/dataset/restricao_coff_fotovoltaica
A10: ONS — fator de capacidade 2 | B10: https://dados.ons.org.br/dataset/fator-capacidade-2 (latitude/longitude e capacidade instalada)
A11: CCEE — PLD médio semanal | B11: https://dadosabertos.ccee.org.br/dataset/pld_media_semanal
A12: CCEE — PLD horário | B12: https://dadosabertos.ccee.org.br/dataset/pld_horario_submercado (usado na versão diária quando já publicado)
A14: Como as contas são feitas
A15: Energia não gerada (MWh) | B15: val_geracaonaorealizadaapurada (GNRa, em MWmed) × 0,5 h — cada registro do ONS é um patamar semi-horário. Só contam os patamares em que o ONS declarou razão de restrição.
A16: % do potencial | B16: Energia não gerada ÷ energia de referência (val_geracaoreferencia × 0,5 h) no período.
A17: Valor (R$) | B17: Energia não gerada × PLD do submercado. NESTA AMOSTRA o PLD é a média semanal da CCEE (o PLD horário de ago/set 2026 ainda não foi publicado); na versão diária usa-se o PLD horário assim que sai. É valor de mercado da energia perdida — custo de oportunidade — e não o ressarcimento de constrained-off apurado pela CCEE.
A18: PLD por mês/submercado | B18: Ver aba 'PLD'. O preço aplicado a cada mês é a média semanal ponderada pelo corte diário daquele submercado.
A20: Razões de restrição (ONS)
A21: REL | B21: Indisponibilidade externa (elétrica)
A22: CNF | B22: Confiabilidade
A23: ENE | B23: Razão energética
A24: PAR | B24: Restrição do parecer de acesso
A26: Aviso | B26: O ONS revisa os dados após a publicação; meses recentes mudam. Números em azul são entradas; os demais são fórmulas.

Sheet Resumo
A1: Resumo por conjunto — usinas fotovoltaicas
A2: Tudo aqui é SUMIFS sobre a aba 'Mensal'; recalcula sozinho se você editar os dados.
A4: Conjunto | B4: ID ONS | C4: Submercado | D4: UF | E4: Capacidade (MW) | F4: REL (MWh) | G4: CNF (MWh) | H4: ENE (MWh) | I4: PAR (MWh) | J4: MWh não gerados | K4: Valor (R$) | L4: R$/MWh médio | M4: Latitude | N4: Longitude | O4: Agente
A5: Assú V | B5: RNFVAE | C5: Nordeste | D5: RN | E5: 34 | F5: =SUMIFS(Mensal!$F$5:$F$169,Mensal!$B$5:$B$169,$B5) -> 143.9 | G5: =SUMIFS(Mensal!$G$5:$G$169,Mensal!$B$5:$B$169,$B5) -> 804.4 | H5: =SUMIFS(Mensal!$H$5:$H$169,Mensal!$B$5:$B$169,$B5) -> 2721.9 | I5: =SUMIFS(Mensal!$I$5:$I$169,Mensal!$B$5:$B$169,$B5) -> 0 | J5: =SUM(F5:I5) -> 3670.2 | K5: =SUMIFS(Mensal!$N$5:$N$169,Mensal!$B$5:$B$169,$B5) -> 499160.8 | L5: =IFERROR(K5/J5,"") -> 136.00371 | M5: -5.5460043 | N5: -37.02639 | O5: ENGIE
A6: Conj. Abaiara 230 kV | B6: CJU_CEAB2 | C6: Nordeste | D6: CE | E6: 163.701 | F6: =SUMIFS(Mensal!$F$5:$F$169,Mensal!$B$5:$B$169,$B6) -> 9 | G6: =SUMIFS(Mensal!$G$5:$G$169,Mensal!$B$5:$B$169,$B6) -> 0 | H6: =SUMIFS(Mensal!$H$5:$H$169,Mensal!$B$5:$B$169,$B6) -> 11784.5 | I6: =SUMIFS(Mensal!$I$5:$I$169,Mensal!$B$5:$B$169,$B6) -> 0 | J6: =SUM(F6:I6) -> 11793.5 | K6: =SUMIFS(Mensal!$N$5:$N$169,Mensal!$B$5:$B$169,$B6) -> 1665680.2 | L6: =IFERROR(K6/J6,"") -> 141.23714 | M6: -7.391467 | N6: -38.970836 | O6: VOLTALIA
A7: Conj. Alex | B7: CJU_CEUFAL | C7: Nordeste | D7: CE | E7: 278.397 | F7: =SUMIFS(Mensal!$F$5:$F$169,Mensal!$B$5:$B$169,$B7) -> 2547.9 | G7: =SUMIFS(Mensal!$G$5:$G$169,Mensal!$B$5:$B$169,$B7) -> 0 | H7: =SUMIFS(Mensal!$H$5:$H$169,Mensal!$B$5:$B$169,$B7) -> 16928.7 | I7: =SUMIFS(Mensal!$I$5:$I$169,Mensal!$B$5:$B$169,$B7) -> 0 | J7: =SUM(F7:I7) -> 19476.6 | K7: =SUMIFS(Mensal!$N$5:$N$169,Mensal!$B$5:$B$169,$B7) -> 2682327.2 | L7: =IFERROR(K7/J7,"") -> 137.7205 | M7: -5.269671 | N7: -37.967945 | O7: ELERA RENOVAVEIS
A8: Conj. Araxá | B8: CJU_MGARX | C8: Sudeste/CO | D8: MG | E8: 90 | F8: =SUMIFS(Mensal!$F$5:$F$169,Mensal!$B$5:$B$169,$B8) -> 0 | G8: =SUMIFS(Mensal!$G$5:$G$169,Mensal!$B$5:$B$169,$B8) -> 0 | H8: =SUMIFS(Mensal!$H$5:$H$169,Mensal!$B$5:$B$169,$B8) -> 9080.1 | I8: =SUMIFS(Mensal!$I$5:$I$169,Mensal!$B$5:$B$169,$B8) -> 0 | J8: =SUM(F8:I8) -> 9080.1 | K8: =SUMIFS(Mensal!$N$5:$N$169,Mensal!$B$5:$B$169,$B8) -> 1248314 | L8: =IFERROR(K8/J8,"") -> 137.478 | M8: -19.762602 | N8: -47.047783 | O8: VISUS ENGENHARIA
A9: Conj. Arinos 2 500 kV | B9: CJU_MGARN | C9: Sudeste/CO | D9: MG | E9: 1189.867 | F9: =SUMIFS(Mensal!$F$5:$F$169,Mensal!$B$5:$B$169,$B9) -> 81.6 | G9: =SUMIFS(Mensal!$G$5:$G$169,Mensal!$B$5:$B$169,$B9) -> 0 | H9: =SUMIFS(Mensal!$H$5:$H$169,Mensal!$B$5:$B$169,$B9) -> 100127.1 | I9: =SUMIFS(Mensal!$I$5:$I$169,Mensal!$B$5:$B$169,$B9) -> 0 | J9: =SUM(F9:I9) -> 100208.7 | K9: =SUMIFS(Mensal!$N$5:$N$169,Mensal!$B$5:$B$169,$B9) -> 14037920 | L9: =IFERROR(K9/J9,"") -> 140.08683 | M9: -15.737569 | N9: -45.965895 | O9: VOLTALIA
A10: Conj. Assu Sol | B10: CJU_RNASO | C10: Nordeste | D10: RN | E10: 752.651 | F10: =SUMIFS(Mensal!$F$5:$F$169,Mensal!$B$5:$B$169,$B10) -> 2729.5 | G10: =SUMIFS(Mensal!$G$5:$G$169,Mensal!$B$5:$B$169,$B10) -> 16074 | H10: =SUMIFS(Mensal!$H$5:$H$169,Mensal!$B$5:$B$169,$B10) -> 66793.5 | I10: =SUMIFS(Mensal!$I$5:$I$169,Mensal!$B$5:$B$169,$B10) -> 0 | J10: =SUM(F10:I10) -> 85597 | K10: =SUMIFS(Mensal!$N$5:$N$169,Mensal!$B$5:$B$169,$B10) -> 11528360 | L10: =IFERROR(K10/J10,"") -> 134.68182 | M10: -5.59 | N10: -37.0346 | O10: ENGIE
A11: Conj. Açú III 230 kV | B11: CJU_RNMEND | C11: Nordeste | D11: RN | E11: 452.412 | F11: =SUMIFS(Mensal!$F$5:$F$169,Mensal!$B$5:$B$169,$B11) -> 2102.6 | G11: =SUMIFS(Mensal!$G$5:$G$169,Mensal!$B$5:$B$169,$B11) -> 9907.1 | H11: =SUMIFS(Mensal!$H$5:$H$169,Mensal!$B$5:$B$169,$B11) -> 36470.4 | I11: =SUMIFS(Mensal!$I$5:$I$169,Mensal!$B$5:$B$169,$B11) -> 0 | J11: =SUM(F11:I11) -> 48480.1 | K11: =SUMIFS(Mensal!$N$5:$N$169,Mensal!$B$5:$B$169,$B11) -> 6340812.6 | L11: =IFERROR(K11/J11,"") -> 130.79207 | M11: -5.615819 | N11: -37.035712 | O11: ENGEPAT
A12: Conj. BJL | B12: CJU_BABJL | C12: Nordeste | D12: BA | E12: 40 | F12: =SUMIFS(Mensal!$F$5:$F$169,Mensal!$B$5:$B$169,$B12) -> 1100.7 | G12: =SUMIFS(Mensal!$G$5:$G$169,Mensal!$B$5:$B$169,$B12) -> 330.6 | H12: =SUMIFS(Mensal!$H$5:$H$169,Mensal!$B$5:$B$169,$B12) -> 4518.2 | I12: =SUMIFS(Mensal!$I$5:$I$169,Mensal!$B$5:$B$169,$B12) -> 0 | J12: =SUM(F12:I12) -> 5949.5 | K12: =SUMIFS(Mensal!$N$5:$N$169,Mensal!$B$5:$B$169,$B12) -> 802489.31 | L12: =IFERROR(K12/J12,"") -> 134.88349 | M12: -13.316116 | N12: -43.46364 | O12: VISUS ENGENHARIA
A13: Conj. Babilônia Centro | B13: CJU_BA4FBBC | C13: Nordeste | D13: BA | E13: 199.96 | F13: =SUMIFS(Mensal!$F$5:$F$169,Mensal!$B$5:$B$169,$B13) -> 510.9 | G13: =SUMIFS(Mensal!$G$5:$G$169,Mensal!$B$5:$B$169,$B13) -> 396.2 | H13: =SUMIFS(Mensal!$H$5:$H$169,Mensal!$B$5:$B$169,$B13) -> 19292.4 | I13: =SUMIFS(Mensal!$I$5:$I$169,Mensal!$B$5:$B$169,$B13) -> 0 | J13: =SUM(F13:I13) -> 20199.5 | K13: =SUMIFS(Mensal!$N$5:$N$169,Mensal!$B$5:$B$169,$B13) -> 2772128.8 | L13: =IFERROR(K13/J13,"") -> 137.2375 | M13: -11.0172 | N13: -41.304 | O13: CVER
A14: Conj. Babilônia Sul | B14: CJU_BA4FBBS | C14: Nordeste | D14: BA | E14: 99.96 | F14: =SUMIFS(Mensal!$F$5:$F$169,Mensal!$B$5:$B$169,$B14) -> 31.6 | G14: =SUMIFS(Mensal!$G$5:$G$169,Mensal!$B$5:$B$169,$B14) -> 187.2 | H14: =SUMIFS(Mensal!$H$5:$H$169,Mensal!$B$5:$B$169,$B14) -> 8788.4 | I14: =SUMIFS(Mensal!$I$5:$I$169,Mensal!$B$5:$B$169,$B14) -> 0 | J14: =SUM(F14:I14) -> 9007.2 | K14: =SUMIFS(Mensal!$N$5:$N$169,Mensal!$B$5:$B$169,$B14) -> 1231545.6 | L14: =IFERROR(K14/J14,"") -> 136.72902 | M14: -11.119977 | N14: -41.290773 | O14: CVER
A15: Conj. Banabuiú | B15: CJU_CEPTN | C15: Nordeste | D15: CE | E15: 230 | F15: =SUMIFS(Mensal!$F$5:$F$169,Mensal!$B$5:$B$169,$B15) -> 2344.6 | G15: =SUMIFS(Mensal!$G$5:$G$169,Mensal!$B$5:$B$169,$B15) -> 934.6 | H15: =SUMIFS(Mensal!$H$5:$H$169,Mensal!$B$5:$B$169,$B15) -> 17927.8 | I15: =SUMIFS(Mensal!$I$5:$I$169,Mensal!$B$5:$B$169,$B15) -> 0 | J15: =SUM(F15:I15) -> 21207 | K15: =SUMIFS(Mensal!$N$5:$N$169,Mensal!$B$5:$B$169,$B15) -> 2925068.9 | L15: =IFERROR(K15/J15,"") -> 137.9294 | M15: -5.3231 | N15: -38.83 | O15: SPIC BRASIL ENERGIA
A16: Conj. Barreiras II 500 kV | B16: CJU_BABRD | C16: Nordeste | D16: BA | E16: 350 | F16: =SUMIFS(Mensal!$F$5:$F$169,Mensal!$B$5:$B$169,$B16) -> 12250.2 | G16: =SUMIFS(Mensal!$G$5:$G$169,Mensal!$B$5:$B$169,$B16) -> 0 | H16: =SUMIFS(Mensal!$H$5:$H$169,Mensal!$B$5:$B$169,$B16) -> 48233.3 | I16: =SUMIFS(Mensal!$I$5:$I$169,Mensal!$B$5:$B$169,$B16) -> 0 | J16: =SUM(F16:I16) -> 60483.5 | K16: =SUMIFS(Mensal!$N$5:$N$169,Mensal!$B$5:$B$169,$B16) -> 8118281.6 | L16: =IFERROR(K16/J16,"") -> 134.22308 | M16: -12.171641 | N16: -44.808283 | O16: ECHOENERGIA
... A19: Conj. Boa Hora | B19: CJU_SPUFBH | C19: Sudeste/CO | D19: SP | E19: 178.33 | F19: =SUMIFS(Mensal!$F$5:$F$169,Mensal!$B$5:$B$169,$B19) -> 0 | G19: =SUMIFS(Mensal!$G$5:$G$169,Mensal!$B$5:$B$169,$B19) -> 0 | H19: =SUMIFS(Mensal!$H$5:$H$169,Mensal!$B$5:$B$169,$B19) -> 17060.7 | I19: =SUMIFS(Mensal!$I$5:$I$169,Mensal!$B$5:$B$169,$B19) -> 0 | J19: =SUM(F19:I19) -> 17060.7 | K19: =SUMIFS(Mensal!$N$5:$N$169,Mensal!$B$5:$B$169,$B19) -> 2327188.2 | L19: =IFERROR(K19/J19,"") -> 136.40637 | M19: -19.881624 | N19: -50.39703 | O19: AUREN OPERAÇÕES
A20: Conj. Boa Sorte | B20: CJU_MGBST1 | C20: Sudeste/CO | D20: MG | F20: =SUMIFS(Mensal!$F$5:$F$169,Mensal!$B$5:$B$169,$B20) -> 0 | G20: =SUMIFS(Mensal!$G$5:$G$169,Mensal!$B$5:$B$169,$B20) -> 0 | H20: =SUMIFS(Mensal!$H$5:$H$169,Mensal!$B$5:$B$169,$B20) -> 30682.8 | I20: =SUMIFS(Mensal!$I$5:$I$169,Mensal!$B$5:$B$169,$B20) -> 0 | J20: =SUM(F20:I20) -> 30682.8 | K20: =SUMIFS(Mensal!$N$5:$N$169,Mensal!$B$5:$B$169,$B20) -> 3966058.7 | L20: =IFERROR(K20/J20,"") -> 129.26 | O20: IQONY
A21: Conj. Bom Jesus | B21: CJU_BABJU | C21: Nordeste | D21: BA | E21: 60 | F21: =SUMIFS(Mensal!$F$5:$F$169,Mensal!$B$5:$B$169,$B21) -> 1617.6 | G21: =SUMIFS(Mensal!$G$5:$G$169,Mensal!$B$5:$B$169,$B21) -> 357 | H21: =SUMIFS(Mensal!$H$5:$H$169,Mensal!$B$5:$B$169,$B21) -> 6305.8 | I21: =SUMIFS(Mensal!$I$5:$I$169,Mensal!$B$5:$B$169,$B21) -> 0 | J21: =SUM(F21:I21) -> 8280.4 | K21: =SUMIFS(Mensal!$N$5:$N$169,Mensal!$B$5:$B$169,$B21) -> 1107378.7 | L21: =IFERROR(K21/J21,"") -> 133.73492 | M21: -13.299456 | N21: -43.33305 | O21: CGN BRASIL
A22: Conj. Bom Nome | B22: CJU_PESPP | C22: Nordeste | D22: PE | E22: 83.914 | F22: =SUMIFS(Mensal!$F$5:$F$169,Mensal!$B$5:$B$169,$B22) -> 260.1 | G22: =SUMIFS(Mensal!$G$5:$G$169,Mensal!$B$5:$B$169,$B22) -> 0 | H22: =SUMIFS(Mensal!$H$5:$H$169,Mensal!$B$5:$B$169,$B22) -> 7818.1 | I22: =SUMIFS(Mensal!$I$5:$I$169,Mensal!$B$5:$B$169,$B22) -> 0 | J22: =SUM(F22:I22) -> 8078.2 | K22: =SUMIFS(Mensal!$N$5:$N$169,Mensal!$B$5:$B$169,$B22) -> 1132933.5 | L22: =IFERROR(K22/J22,"") -> 140.24578 | M22: -7.8725076 | N22: -37.97911 | O22: VOLTALIA
A23: Conj. Brígida | B23: CJU_PEBRI | C23: Nordeste | D23: PE | E23: 163 | F23: =SUMIFS(Mensal!$F$5:$F$169,Mensal!$B$5:$B$169,$B23) -> 336.8 | G23: =SUMIFS(Mensal!$G$5:$G$169,Mensal!$B$5:$B$169,$B23) -> 0 | H23: =SUMIFS(Mensal!$H$5:$H$169,Mensal!$B$5:$B$169,$B23) -> 12871.3 | I23: =SUMIFS(Mensal!$I$5:$I$169,Mensal!$B$5:$B$169,$B23) -> 0 | J23: =SUM(F23:I23) -> 13208.1 | K23: =SUMIFS(Mensal!$N$5:$N$169,Mensal!$B$5:$B$169,$B23) -> 1823750.3 | L23: =IFERROR(K23/J23,"") -> 138.07817 | M23: -8.565919 | N23: -39.591642 | O23: IQONY
A24: Conj. Calcário | B24: CJU_CECAL | C24: Nordeste | D24: CE | E24: 132 | F24: =SUMIFS(Mensal!$F$5:$F$169,Mensal!$B$5:$B$169,$B24) -> 1280.7 | G24: =SUMIFS(Mensal!$G$5:$G$169,Mensal!$B$5:$B$169,$B24) -> 99 | H24: =SUMIFS(Mensal!$H$5:$H$169,Mensal!$B$5:$B$169,$B24) -> 7358.2 | I24: =SUMIFS(Mensal!$I$5:$I$169,Mensal!$B$5:$B$169,$B24) -> 0 | J24: =SUM(F24:I24) -> 8737.9 | K24: =SUMIFS(Mensal!$N$5:$N$169,Mensal!$B$5:$B$169,$B24) -> 1191388.8 | L24: =IFERROR(K24/J24,"") -> 136.34727 | M24: -5.0347 | N24: -37.785 | O24: ENGEPAT
A25: Conj. Castilho | B25: CJU_SPCST3 | C25: Sudeste/CO | D25: SP | E25: 205.04 | F25: =SUMIFS(Mensal!$F$5:$F$169,Mensal!$B$5:$B$169,$B25) -> 0 | G25: =SUMIFS(Mensal!$G$5:$G$169,Mensal!$B$5:$B$169,$B25) -> 0 | H25: =SUMIFS(Mensal!$H$5:$H$169,Mensal!$B$5:$B$169,$B25) -> 17423.6 | I25: =SUMIFS(Mensal!$I$5:$I$169,Mensal!$B$5:$B$169,$B25) -> 0 | J25: =SUM(F25:I25) -> 17423.6 | K25: =SUMIFS(Mensal!$N$5:$N$169,Mensal!$B$5:$B$169,$B25) -> 2359937.5 | L25: =IFERROR(K25/J25,"") -> 135.44488 | M25: -20.790444 | N25: -51.529266 | O25: COTESA
A26: Conj. Ciranda | B26: CJU_PECIR | C26: Nordeste | D26: PE | E26: 244.5 | F26: =SUMIFS(Mensal!$F$5:$F$169,Mensal!$B$5:$B$169,$B26) -> 475.1 | G26: =SUMIFS(Mensal!$G$5:$G$169,Mensal!$B$5:$B$169,$B26) -> 0 | H26: =SUMIFS(Mensal!$H$5:$H$169,Mensal!$B$5:$B$169,$B26) -> 14138.6 | I26: =SUMIFS(Mensal!$I$5:$I$169,Mensal!$B$5:$B$169,$B26) -> 0 | J26: =SUM(F26:I26) -> 14613.7 | K26: =SUMIFS(Mensal!$N$5:$N$169,Mensal!$B$5:$B$169,$B26) -> 2041752.7 | L26: =IFERROR(K26/J26,"") -> 139.71497 | M26: -7.963652 | N26: -38.627376 | O26: VISUS ENGENHARIA
A27: Conj. Dracena | B27: CJU_SPUFD | C27: Sudeste/CO | D27: SP | E27: 81 | F27: =SUMIFS(Mensal!$F$5:$F$169,Mensal!$B$5:$B$169,$B27) -> 0 | G27: =SUMIFS(Mensal!$G$5:$G$169,Mensal!$B$5:$B$169,$B27) -> 0 | H27: =SUMIFS(Mensal!$H$5:$H$169,Mensal!$B$5:$B$169,$B27) -> 7414.8 | I27: =SUMIFS(Mensal!$I$5:$I$169,Mensal!$B$5:$B$169,$B27) -> 0 | J27: =SUM(F27:I27) -> 7414.8 | K27: =SUMIFS(Mensal!$N$5:$N$169,Mensal!$B$5:$B$169,$B27) -> 994648.8 | L27: =IFERROR(K27/J27,"") -> 134.14371 | M27: -21.450214 | N27: -51.587776 | O27: COTESA
A28: Conj. Draco | B28: CJU_MGDRC | C28: Sudeste/CO | D28: MG | E28: 505.243 | F28: =SUMIFS(Mensal!$F$5:$F$169,Mensal!$B$5:$B$169,$B28) -> 63.2 | G28: =SUMIFS(Mensal!$G$5:$G$169,Mensal!$B$5:$B$169,$B28) -> 0 | H28: =SUMIFS(Mensal!$H$5:$H$169,Mensal!$B$5:$B$169,$B28) -> 47891.7 | I28: =SUMIFS(Mensal!$I$5:$I$169,Mensal!$B$5:$B$169,$B28) -> 0 | J28: =SUM(F28:I28) -> 47954.9 | K28: =SUMIFS(Mensal!$N$5:$N$169,Mensal!$B$5:$B$169,$B28) -> 6646542.1 | L28: =IFERROR(K28/J28,"") -> 138.59985 | O28: VOLTALIA
A29: Conj. Floresta | B29: CJU_RNFLO | C29: Nordeste | D29: RN | E29: 86 | F29: =SUMIFS(Mensal!$F$5:$F$169,Mensal!$B$5:$B$169,$B29) -> 281.1 | G29: =SUMIFS(Mensal!$G$5:$G$169,Mensal!$B$5:$B$169,$B29) -> 16.8 | H29: =SUMIFS(Mensal!$H$5:$H$169,Mensal!$B$5:$B$169,$B29) -> 2735.3 | I29: =SUMIFS(Mensal!$I$5:$I$169,Mensal!$B$5:$B$169,$B29) -> 0 | J29: =SUM(F29:I29) -> 3033.2 | K29: =SUMIFS(Mensal!$N$5:$N$169,Mensal!$B$5:$B$169,$B29) -> 414299.59 | L29: =IFERROR(K29/J29,"") -> 136.58829 | M29: -4.963689 | N29: -36.916961 | O29: AUREN OPERAÇÕES
A30: Conj. Fot. Brotas de Macaúbas 230 kV | B30: CJU_BA4FBMC | C30: Nordeste | D30: BA | E30: 65 | F30: =SUMIFS(Mensal!$F$5:$F$169,Mensal!$B$5:$B$169,$B30) -> 183.8 | G30: =SUMIFS(Mensal!$G$5:$G$169,Mensal!$B$5:$B$169,$B30) -> 0 | H30: =SUMIFS(Mensal!$H$5:$H$169,Mensal!$B$5:$B$169,$B30) -> 1531.1 | I30: =SUMIFS(Mensal!$I$5:$I$169,Mensal!$B$5:$B$169,$B30) -> 0 | J30: =SUM(F30:I30) -> 1714.9 | K30: =SUMIFS(Mensal!$N$5:$N$169,Mensal!$B$5:$B$169,$B30) -> 234432.15 | L30: =IFERROR(K30/J30,"") -> 136.7031 | M30: -12.30836 | N30: -42.343268 | O30: STATKRAFT
A31: Conj. Francisco Sá | B31: CJU_MGFSA | C31: Sudeste/CO | D31: MG | E31: 99 | F31: =SUMIFS(Mensal!$F$5:$F$169,Mensal!$B$5:$B$169,$B31) -> 1171.6 | G31: =SUMIFS(Mensal!$G$5:$G$169,Mensal!$B$5:$B$169,$B31) -> 0 | H31: =SUMIFS(Mensal!$H$5:$H$169,Mensal!$B$5:$B$169,$B31) -> 7662.9 | I31: =SUMIFS(Mensal!$I$5:$I$169,Mensal!$B$5:$B$169,$B31) -> 0 | J31: =SUM(F31:I31) -> 8834.5 | K31: =SUMIFS(Mensal!$N$5:$N$169,Mensal!$B$5:$B$169,$B31) -> 1211041.3 | L31: =IFERROR(K31/J31,"") -> 137.08091 | M31: -16.2937 | N31: -43.6646 | O31: BEI BRASIL ENER INT
A32: Conj. Futura | B32: CJU_BAFFUT | C32: Nordeste | D32: BA | E32: 692.446 | F32: =SUMIFS(Mensal!$F$5:$F$169,Mensal!$B$5:$B$169,$B32) -> 2961.1 | G32: =SUMIFS(Mensal!$G$5:$G$169,Mensal!$B$5:$B$169,$B32) -> 805 | H32: =SUMIFS(Mensal!$H$5:$H$169,Mensal!$B$5:$B$169,$B32) -> 47309.8 | I32: =SUMIFS(Mensal!$I$5:$I$169,Mensal!$B$5:$B$169,$B32) -> 0 | J32: =SUM(F32:I32) -> 51075.9 | K32: =SUMIFS(Mensal!$N$5:$N$169,Mensal!$B$5:$B$169,$B32) -> 7053718.4 | L32: =IFERROR(K32/J32,"") -> 138.10268 | M32: -9.660782 | N32: -40.686021 | O32: ENEVA
A33: Conj. Gilbués II 500 kV | B33: CJU_PI5FGID | C33: Nordeste | D33: PI | E33: 790.885 | F33: =SUMIFS(Mensal!$F$5:$F$169,Mensal!$B$5:$B$169,$B33) -> 6533.1 | G33: =SUMIFS(Mensal!$G$5:$G$169,Mensal!$B$5:$B$169,$B33) -> 0 | H33: =SUMIFS(Mensal!$H$5:$H$169,Mensal!$B$5:$B$169,$B33) -> 62350.9 | I33: =SUMIFS(Mensal!$I$5:$I$169,Mensal!$B$5:$B$169,$B33) -> 0 | J33: =SUM(F33:I33) -> 68884 | K33: =SUMIFS(Mensal!$N$5:$N$169,Mensal!$B$5:$B$169,$B33) -> 9469197.6 | L33: =IFERROR(K33/J33,"") -> 137.46585 | M33: -10.103855 | N33: -45.282352 | O33: ENEL
A34: Conj. Guaimbê | B34: CJU_SPCUFG | C34: Sudeste/CO | D34: SP | E34: 150.04 | F34: =SUMIFS(Mensal!$F$5:$F$169,Mensal!$B$5:$B$169,$B34) -> 0 | G34: =SUMIFS(Mensal!$G$5:$G$169,Mensal!$B$5:$B$169,$B34) -> 0 | H34: =SUMIFS(Mensal!$H$5:$H$169,Mensal!$B$5:$B$169,$B34) -> 9697.8 | I34: =SUMIFS(Mensal!$I$5:$I$169,Mensal!$B$5:$B$169,$B34) -> 0 | J34: =SUM(F34:I34) -> 9697.8 | K34: =SUMIFS(Mensal!$N$5:$N$169,Mensal!$B$5:$B$169,$B34) -> 1290770.6 | L34: =IFERROR(K34/J34,"") -> 133.09932 | M34: -21.893809 | N34: -49.863684 | O34: AUREN OPERAÇÕES
A35: Conj. Helio Valgas | B35: CJU_MGVZPQ | C35: Sudeste/CO | D35: MG | E35: 500 | F35: =SUMIFS(Mensal!$F$5:$F$169,Mensal!$B$5:$B$169,$B35) -> 0 | G35: =SUMIFS(Mensal!$G$5:$G$169,Mensal!$B$5:$B$169,$B35) -> 0 | H35: =SUMIFS(Mensal!$H$5:$H$169,Mensal!$B$5:$B$169,$B35) -> 47536.7 | I35: =SUMIFS(Mensal!$I$5:$I$169,Mensal!$B$5:$B$169,$B35) -> 0 | J35: =SUM(F35:I35) -> 47536.7 | K35: =SUMIFS(Mensal!$N$5:$N$169,Mensal!$B$5:$B$169,$B35) -> 6560348.2 | L35: =IFERROR(K35/J35,"") -> 138.00597 | M35: -17.578819 | N35: -44.642562 | O35: COTESA
A36: Conj. Horizonte | B36: CJU_BAHZT | C36: Nordeste | D36: BA | E36: 79.8 | F36: =SUMIFS(Mensal!$F$5:$F$169,Mensal!$B$5:$B$169,$B36) -> 2282.1 | G36: =SUMIFS(Mensal!$G$5:$G$169,Mensal!$B$5:$B$169,$B36) -> 0 | H36: =SUMIFS(Mensal!$H$5:$H$169,Mensal!$B$5:$B$169,$B36) -> 10441.9 | I36: =SUMIFS(Mensal!$I$5:$I$169,Mensal!$B$5:$B$169,$B36) -> 0 | J36: =SUM(F36:I36) -> 12724 | K36: =SUMIFS(Mensal!$N$5:$N$169,Mensal!$B$5:$B$169,$B36) -> 1720613.5 | L36: =IFERROR(K36/J36,"") -> 135.22584 | M36: -12.604269 | N36: -44.083244 | O36: ENEL
A37: Conj. Icó 230 kV | B37: CJU_CE4FICO | C37: Nordeste | D37: CE | E37: 189.14 | F37: =SUMIFS(Mensal!$F$5:$F$169,Mensal!$B$5:$B$169,$B37) -> 692.8 | G37: =SUMIFS(Mensal!$G$5:$G$169,Mensal!$B$5:$B$169,$B37) -> 0 | H37: =SUMIFS(Mensal!$H$5:$H$169,Mensal!$B$5:$B$169,$B37) -> 16688.6 | I37: =SUMIFS(Mensal!$I$5:$I$169,Mensal!$B$5:$B$169,$B37) -> 0 | J37: =SUM(F37:I37) -> 17381.4 | K37: =SUMIFS(Mensal!$N$5:$N$169,Mensal!$B$5:$B$169,$B37) -> 2411503.6 | L37: =IFERROR(K37/J37,"") -> 138.74047 | M37: -6.357122 | N37: -38.86369 | O37: QAIR BRASIL
A38: Conj. Inocência 230 kV | B38: CJU_MS4FINO | C38: Sudeste/CO | D38: MS | E38: 400 | F38: =SUMIFS(Mensal!$F$5:$F$169,Mensal!$B$5:$B$169,$B38) -> 0 | G38: =SUMIFS(Mensal!$G$5:$G$169,Mensal!$B$5:$B$169,$B38) -> 0 | H38: =SUMIFS(Mensal!$H$5:$H$169,Mensal!$B$5:$B$169,$B38) -> 1071.7 | I38: =SUMIFS(Mensal!$I$5:$I$169,Mensal!$B$5:$B$169,$B38) -> 0 | J38: =SUM(F38:I38) -> 1071.7 | K38: =SUMIFS(Mensal!$N$5:$N$169,Mensal!$B$5:$B$169,$B38) -> 195419.97 | L38: =IFERROR(K38/J38,"") -> 182.34577 | M38: -19.77375 | N38: -51.389267 | O38: CVER
A39: Conj. Irecê 138 kV | B39: CJU_BA3FIRE | C39: Nordeste | D39: BA | E39: 133.401 | F39: =SUMIFS(Mensal!$F$5:$F$169,Mensal!$B$5:$B$169,$B39) -> 0 | G39: =SUMIFS(Mensal!$G$5:$G$169,Mensal!$B$5:$B$169,$B39) -> 3275.6 | H39: =SUMIFS(Mensal!$H$5:$H$169,Mensal!$B$5:$B$169,$B39) -> 12534.5 | I39: =SUMIFS(Mensal!$I$5:$I$169,Mensal!$B$5:$B$169,$B39) -> 0 | J39: =SUM(F39:I39) -> 15810.1 | K39: =SUMIFS(Mensal!$N$5:$N$169,Mensal!$B$5:$B$169,$B39) -> 2154995.1 | L39: =IFERROR(K39/J39,"") -> 136.30497 | M39: -11.308639 | N39: -41.80786 | O39: IQONY
A40: Conj. Ituverava | B40: CJU_BATBV | C40: Nordeste | D40: BA | E40: 196 | F40: =SUMIFS(Mensal!$F$5:$F$169,Mensal!$B$5:$B$169,$B40) -> 5668 | G40: =SUMIFS(Mensal!$G$5:$G$169,Mensal!$B$5:$B$169,$B40) -> 0 | H40: =SUMIFS(Mensal!$H$5:$H$169,Mensal!$B$5:$B$169,$B40) -> 26356.5 | I40: =SUMIFS(Mensal!$I$5:$I$169,Mensal!$B$5:$B$169,$B40) -> 0 | J40: =SUM(F40:I40) -> 32024.5 | K40: =SUMIFS(Mensal!$N$5:$N$169,Mensal!$B$5:$B$169,$B40) -> 4309773 | L40: =IFERROR(K40/J40,"") -> 134.57737 | M40: -12.583701 | N40: -44.107733 | O40: ENEL
A41: Conj. Jaguaruana II 230kV | B41: CJU_CEAPA | C41: Nordeste | D41: CE | E41: 199.8 | F41: =SUMIFS(Mensal!$F$5:$F$169,Mensal!$B$5:$B$169,$B41) -> 803.3 | G41: =SUMIFS(Mensal!$G$5:$G$169,Mensal!$B$5:$B$169,$B41) -> 164.5 | H41: =SUMIFS(Mensal!$H$5:$H$169,Mensal!$B$5:$B$169,$B41) -> 14729.4 | I41: =SUMIFS(Mensal!$I$5:$I$169,Mensal!$B$5:$B$169,$B41) -> 0 | J41: =SUM(F41:I41) -> 15697.2 | K41: =SUMIFS(Mensal!$N$5:$N$169,Mensal!$B$5:$B$169,$B41) -> 2185597.8 | L41: =IFERROR(K41/J41,"") -> 139.23488 | M41: -4.9378 | N41: -37.7046 | O41: VOLTALIA
A42: Conj. Jaiba 138 kV | B42: CJU_MGJAI3 | C42: Sudeste/CO | D42: MG | E42: 120 | F42: =SUMIFS(Mensal!$F$5:$F$169,Mensal!$B$5:$B$169,$B42) -> 1881.5 | G42: =SUMIFS(Mensal!$G$5:$G$169,Mensal!$B$5:$B$169,$B42) -> 0 | H42: =SUMIFS(Mensal!$H$5:$H$169,Mensal!$B$5:$B$169,$B42) -> 10773.8 | I42: =SUMIFS(Mensal!$I$5:$I$169,Mensal!$B$5:$B$169,$B42) -> 0 | J42: =SUM(F42:I42) -> 12655.3 | K42: =SUMIFS(Mensal!$N$5:$N$169,Mensal!$B$5:$B$169,$B42) -> 1721231.3 | L42: =IFERROR(K42/J42,"") -> 136.00873 | O42: VISUS ENGENHARIA
A43: Conj. Janaúba | B43: CJU_MGJAN | C43: Sudeste/CO | D43: MG | E43: 1336.658 | F43: =SUMIFS(Mensal!$F$5:$F$169,Mensal!$B$5:$B$169,$B43) -> 17048.3 | G43: =SUMIFS(Mensal!$G$5:$G$169,Mensal!$B$5:$B$169,$B43) -> 0 | H43: =SUMIFS(Mensal!$H$5:$H$169,Mensal!$B$5:$B$169,$B43) -> 100528.6 | I43: =SUMIFS(Mensal!$I$5:$I$169,Mensal!$B$5:$B$169,$B43) -> 0 | J43: =SUM(F43:I43) -> 117576.9 | K43: =SUMIFS(Mensal!$N$5:$N$169,Mensal!$B$5:$B$169,$B43) -> 15861307 | L43: =IFERROR(K43/J43,"") -> 134.90155 | M43: -15.94656 | N43: -43.508374 | O43: ELERA RENOVAVEIS
...

Sheet Mensal
A1: Energia não gerada por conjunto e mês — dados do ONS
A2: Valores em azul vêm direto dos arquivos do ONS/CCEE.
A4: Conjunto | B4: ID ONS | C4: Submercado | D4: UF | E4: Mês | F4: REL (MWh) | G4: CNF (MWh) | H4: ENE (MWh) | I4: PAR (MWh) | J4: MWh não gerados | K4: Energia de referência (MWh) | L4: % do potencial | M4: PLD aplicado (R$/MWh) | N4: Valor (R$)
A5: Assú V | B5: RNFVAE | C5: Nordeste | D5: RN | E5: 46235 | F5: 143.9 | G5: 722.2 | H5: 2245.5 | I5: 0 | J5: =SUM(F5:I5) -> 3111.6 | K5: 6780 | L5: =IFERROR(J5/K5,"") -> 0.45893805 | M5: 127.96 | N5: =J5*M5 -> 398160.34
A6: Assú V | B6: RNFVAE | C6: Nordeste | D6: RN | E6: 46266 | F6: 0 | G6: 82.2 | H6: 476.4 | I6: 0 | J6: =SUM(F6:I6) -> 558.6 | K6: 1733 | L6: =IFERROR(J6/K6,"") -> 0.32233122 | M6: 180.81 | N6: =J6*M6 -> 101000.47
A7: Conj. Abaiara 230 kV | B7: CJU_CEAB2 | C7: Nordeste | D7: CE | E7: 46235 | F7: 9 | G7: 0 | H7: 8821.7 | I7: 0 | J7: =SUM(F7:I7) -> 8830.7 | K7: 39179 | L7: =IFERROR(J7/K7,"") -> 0.22539371 | M7: 127.96 | N7: =J7*M7 -> 1129976.4
A8: Conj. Abaiara 230 kV | B8: CJU_CEAB2 | C8: Nordeste | D8: CE | E8: 46266 | F8: 0 | G8: 0 | H8: 2962.8 | I8: 0 | J8: =SUM(F8:I8) -> 2962.8 | K8: 9241 | L8: =IFERROR(J8/K8,"") -> 0.32061465 | M8: 180.81 | N8: =J8*M8 -> 535703.87
A9: Conj. Alex | B9: CJU_CEUFAL | C9: Nordeste | D9: CE | E9: 46235 | F9: 2547.9 | G9: 0 | H9: 13331.7 | I9: 0 | J9: =SUM(F9:I9) -> 15879.6 | K9: 65658 | L9: =IFERROR(J9/K9,"") -> 0.24185324 | M9: 127.96 | N9: =J9*M9 -> 2031953.6
A10: Conj. Alex | B10: CJU_CEUFAL | C10: Nordeste | D10: CE | E10: 46266 | F10: 0 | G10: 0 | H10: 3597 | I10: 0 | J10: =SUM(F10:I10) -> 3597 | K10: 15177 | L10: =IFERROR(J10/K10,"") -> 0.23700336 | M10: 180.81 | N10: =J10*M10 -> 650373.57
A11: Conj. Araxá | B11: CJU_MGARX | C11: Sudeste/CO | D11: MG | E11: 46235 | F11: 0 | G11: 0 | H11: 7677.2 | I11: 0 | J11: =SUM(F11:I11) -> 7677.2 | K11: 20272 | L11: =IFERROR(J11/K11,"") -> 0.37870955 | M11: 129.26 | N11: =J11*M11 -> 992354.87
A12: Conj. Araxá | B12: CJU_MGARX | C12: Sudeste/CO | D12: MG | E12: 46266 | F12: 0 | G12: 0 | H12: 1402.9 | I12: 0 | J12: =SUM(F12:I12) -> 1402.9 | K12: 3874 | L12: =IFERROR(J12/K12,"") -> 0.36213216 | M12: 182.45 | N12: =J12*M12 -> 255959.11
A13: Conj. Arinos 2 500 kV | B13: CJU_MGARN | C13: Sudeste/CO | D13: MG | E13: 46235 | F13: 81.6 | G13: 0 | H13: 79729.6 | I13: 0 | J13: =SUM(F13:I13) -> 79811.2 | K13: 287941 | L13: =IFERROR(J13/K13,"") -> 0.27717901 | M13: 129.26 | N13: =J13*M13 -> 10316396
A14: Conj. Arinos 2 500 kV | B14: CJU_MGARN | C14: Sudeste/CO | D14: MG | E14: 46266 | F14: 0 | G14: 0 | H14: 20397.5 | I14: 0 | J14: =SUM(F14:I14) -> 20397.5 | K14: 57310 | L14: =IFERROR(J14/K14,"") -> 0.3559152 | M14: 182.45 | N14: =J14*M14 -> 3721523.9
A15: Conj. Assu Sol | B15: CJU_RNASO | C15: Nordeste | D15: RN | E15: 46235 | F15: 2729.5 | G15: 15000.9 | H15: 56979.8 | I15: 0 | J15: =SUM(F15:I15) -> 74710.2 | K15: 171861 | L15: =IFERROR(J15/K15,"") -> 0.43471294 | M15: 127.96 | N15: =J15*M15 -> 9559917.2
A16: Conj. Assu Sol | B16: CJU_RNASO | C16: Nordeste | D16: RN | E16: 46266 | F16: 0 | G16: 1073.1 | H16: 9813.7 | I16: 0 | J16: =SUM(F16:I16) -> 10886.8 | K16: 42315 | L16: =IFERROR(J16/K16,"") -> 0.25727992 | M16: 180.81 | N16: =J16*M16 -> 1968442.3
... A169: Sol do Piauí | B169: PISDP1 | C169: Nordeste | D169: PI | E169: 46266 | F169: 0 | G169: 0 | H169: 987 | I169: 0 | J169: =SUM(F169:I169) -> 987 | K169: 2561 | L169: =IFERROR(J169/K169,"") -> 0.38539633 | M169: 180.81 | N169: =J169*M169 -> 178459.47

Sheet PLD
A1: PLD médio semanal por submercado — CCEE Dados Abertos
A2: Semanas CCEE começam no sábado. Fonte: dadosabertos.ccee.org.br/dataset/pld_media_semanal (resource pld_media_semanal_2026).
A4: Semana (início) | B4: Submercado | C4: PLD (R$/MWh)
A5: 46228 | B5: Norte | C5: 146.19
A6: 46235 | B6: Norte | C6: 117.88
A7: 46242 | B7: Norte | C7: 128.48
A8: 46249 | B8: Norte | C8: 117.92
A9: 46256 | B9: Norte | C9: 125.37
A10: 46263 | B10: Norte | C10: 181.81
A11: 46228 | B11: Nordeste | C11: 146.13
A12: 46235 | B12: Nordeste | C12: 117.82
A13: 46242 | B13: Nordeste | C13: 128.4
A14: 46249 | B14: Nordeste | C14: 115.66
A15: 46256 | B15: Nordeste | C15: 121.7
A16: 46263 | B16: Nordeste | C16: 180.81
... A28: 46263 | B28: Sudeste/CO | C28: 182.45
